<?xml version="1.0" ?>
<!-- =================================================================================== -->
<!-- |    This document was autogenerated by xacro from robo.xacro                     | -->
<!-- |    EDITING THIS FILE BY HAND IS NOT RECOMMENDED                                 | -->
<!-- =================================================================================== -->
<robot name="lols">
  <material name="black">
    <color rgba="0.0 0.0 0.0 1.0"/>
  </material>
  <material name="blue">
    <color rgba="0.0 0.0 0.8 1.0"/>
  </material>
  <material name="green">
    <color rgba="0.0 0.8 0.0 1.0"/>
  </material>
  <material name="grey">
    <color rgba="0.2 0.2 0.2 1.0"/>
  </material>
  <material name="orange">
    <color rgba="1.0 0.4235294117647059 0.0392156862745098 1.0"/>
  </material>
  <material name="brown">
    <color rgba="0.8705882352941177 0.8117647058823529 0.7647058823529411 1.0"/>
  </material>
  <material name="red">
    <color rgba="0.8 0.0 0.0 1.0"/>
  </material>
  <material name="white">
    <color rgba="1.0 1.0 1.0 1.0"/>
  </material>
  <gazebo>
    <static>False</static>
  </gazebo>
  <link name="dummy"/>
  <joint name="dummy_joint" type="fixed">
    <origin rpy="0.0 0.0 0.0" xyz="0.0 0.0 1"/>
    <parent link="dummy"/>
    <child link="base_link"/>
  </joint>
  <!-- Base Link -->
  <link name="base_link">
    <pose>0 0 3 0 0 0</pose>
    <visual>
      <material name="white"/>
      <origin rpy="0 0 0" xyz="0 0 0.05"/>
      <geometry>
        <box size="1 0.5 0.25"/>
      </geometry>
    </visual>
    <!-- Base collision, mass and inertia -->
    <collision>
      <origin rpy="0 0 0" xyz="0 0 0.05"/>
      <geometry>
        <box size="1 0.5 0.25"/>
      </geometry>
    </collision>
    <inertial>
      <mass value="5"/>
      <inertia ixx="0.13020833333333334" ixy="0" ixz="0" iyy="0.4427083333333333" iyz="0" izz="0.4427083333333333"/>
    </inertial>
  </link>
  <gazebo reference="base_link">
    <material>Gazebo/White</material>
  </gazebo>
  <link name="link_front_left_wheel">
    <inertial>
      <mass value="0.2"/>
      <origin rpy="0 1.5707963267948966 1.5707963267948966" xyz="0 0 0"/>
      <inertia ixx="0.0021666666666666674" ixy="0" ixz="0" iyy="0.0021666666666666674" iyz="0" izz="0.004000000000000001"/>
    </inertial>
    <collision>
      <origin rpy="0 1.5707963267948966 1.5707963267948966" xyz="0 0 0"/>
      <geometry>
        <cylinder length="0.1" radius="0.2"/>
      </geometry>
    </collision>
    <visual>
      <origin rpy="0 1.5707963267948966 1.5707963267948966" xyz="0 0 0"/>
      <geometry>
        <cylinder length="0.1" radius="0.2"/>
      </geometry>
    </visual>
  </link>
  <joint name="joint_front_left_wheel" type="continuous">
    <origin rpy="0 0 0" xyz="0.3 0.25 0"/>
    <child link="link_front_left_wheel"/>
    <parent link="link_chassis"/>
    <axis rpy="0 0 0" xyz="0 1 0"/>
  </joint>
  <!-- <xacro:define_wheel pos_fb="front" pos_lr="right" reflect_fb="1" reflect_lr="-1" /> -->
  <!-- <xacro:define_wheel pos_fb="back" pos_lr="left" reflect_fb="-1" reflect_lr="1" /> -->
  <!-- <xacro:define_wheel pos_fb="back" pos_lr="right" reflect_fb="-1" reflect_lr="-1" /> -->
</robot>
